Workbook

Sheet Продажі факт
A1: № чеку | B1: Дата продажу | C1: Час продажу | D1: Товар ID новий | E1: Кількість | F1: Виручка, грн | G1: Спосіб оплати | H1: Покупець | I1: Магазин | J1: Собівартість, грн | K1: Дата відвантаження | L1: Бренд
A2: 100000001 | B2: 43018 | C2: 0.56505787 | D2: 10138 | E2: 1 | F2: 158.32913 | G2: готівковий | I2: Магазин №4 Київ | J2: 68.25 | K2: 43023 | L2: =VLOOKUP(D2, 'Список товарів'!$B$2:$D$341, 2, FALSE) -> Adidas
A3: 100000001 | B3: 43018 | C3: 0.56505787 | D3: 10260 | E3: 1 | F3: 1890.2016 | G3: готівковий | I3: Магазин №4 Київ | J3: 1254.04 | K3: 43023 | L3: =VLOOKUP(D3, 'Список товарів'!$B$2:$D$341, 2, FALSE) -> Reebok
A4: 100000002 | B4: 42763 | C4: 0.66717593 | D4: 10046 | E4: 1 | F4: 296.82042 | G4: готівковий | I4: Магазин №3 Київ | J4: 212.01 | K4: 42767 | L4: =VLOOKUP(D4, 'Список товарів'!$B$2:$D$341, 2, FALSE) -> Nike
A5: 100000003 | B5: 43124 | C5: 0.59202546 | D5: 10028 | E5: 1 | F5: 940.15152 | G5: готівковий | I5: Магазин №6 Київ | J5: 384.3 | K5: 43124 | L5: =VLOOKUP(D5, 'Список товарів'!$B$2:$D$341, 2, FALSE) -> Nike
A6: 100000003 | B6: 43124 | C6: 0.59202546 | D6: 10312 | E6: 1 | F6: 502.398 | G6: готівковий | I6: Магазин №6 Київ | J6: 219.22 | K6: 43124 | L6: =VLOOKUP(D6, 'Список товарів'!$B$2:$D$341, 2, FALSE) -> Reebok
A7: 100000004 | B7: 42621 | C7: 0.85002315 | D7: 10293 | E7: 1 | F7: 136.67859 | G7: безготівковий | I7: Магазин №3 Київ | J7: 116.63 | K7: 42621 | L7: =VLOOKUP(D7, 'Список товарів'!$B$2:$D$341, 2, FALSE) -> Reebok
A8: 100000005 | B8: 42758 | C8: 0.47431713 | D8: 10304 | E8: 1 | F8: 627.41952 | G8: готівковий | H8: ПІБ 1058 | I8: Магазин №5 Київ | J8: 406.6 | K8: 42758 | L8: =VLOOKUP(D8, 'Список товарів'!$B$2:$D$341, 2, FALSE) -> Reebok
A9: 100000005 | B9: 42758 | C9: 0.47431713 | D9: 10182 | E9: 1 | F9: 3472.6982 | G9: готівковий | H9: ПІБ 1058 | I9: Магазин №5 Київ | J9: 2967.84 | K9: 42758 | L9: =VLOOKUP(D9, 'Список товарів'!$B$2:$D$341, 2, FALSE) -> Puma
A10: 100000005 | B10: 42758 | C10: 0.47431713 | D10: 10271 | E10: 1 | F10: 4895.296 | G10: готівковий | H10: ПІБ 1058 | I10: Магазин №5 Київ | J10: 3652.74 | K10: 42758 | L10: =VLOOKUP(D10, 'Список товарів'!$B$2:$D$341, 2, FALSE) -> Reebok
A11: 100000007 | B11: 43273 | C11: 0.65077546 | D11: 10239 | E11: 1 | F11: 752.03568 | G11: готівковий | H11: ПІБ 906 | I11: Магазин №7 Київ | J11: 482 | K11: 43273 | L11: =VLOOKUP(D11, 'Список товарів'!$B$2:$D$341, 2, FALSE) -> Puma
A12: 100000007 | B12: 43273 | C12: 0.65077546 | D12: 10071 | E12: 1 | F12: 1221.7606 | G12: готівковий | H12: ПІБ 906 | I12: Магазин №7 Київ | J12: 652.01 | K12: 43273 | L12: =VLOOKUP(D12, 'Список товарів'!$B$2:$D$341, 2, FALSE) -> Nike
A13: 100000007 | B13: 43273 | C13: 0.65077546 | D13: 10172 | E13: 1 | F13: 1484.3126 | G13: готівковий | H13: ПІБ 906 | I13: Магазин №7 Київ | J13: 1148.94 | K13: 43273 | L13: =VLOOKUP(D13, 'Список товарів'!$B$2:$D$341, 2, FALSE) -> Puma
A14: 100000007 | B14: 43273 | C14: 0.65077546 | D14: 10207 | E14: 2 | F14: 435.6697 | G14: готівковий | H14: ПІБ 906 | I14: Магазин №7 Київ | J14: 268.8 | K14: 43273 | L14: =VLOOKUP(D14, 'Список товарів'!$B$2:$D$341, 2, FALSE) -> Puma
A15: 100000007 | B15: 43273 | C15: 0.65077546 | D15: 10046 | E15: 1 | F15: 392.6196 | G15: готівковий | H15: ПІБ 906 | I15: Магазин №7 Київ | J15: 227.29 | K15: 43273 | L15: =VLOOKUP(D15, 'Список товарів'!$B$2:$D$341, 2, FALSE) -> Nike
A16: 100000007 | B16: 43273 | C16: 0.65077546 | D16: 10015 | E16: 1 | F16: 6086.7532 | G16: готівковий | H16: ПІБ 906 | I16: Магазин №7 Київ | J16: 2051.1 | K16: 43273 | L16: =VLOOKUP(D16, 'Список товарів'!$B$2:$D$341, 2, FALSE) -> Nike
A17: 100000007 | B17: 43273 | C17: 0.65077546 | D17: 10311 | E17: 1 | F17: 373.644 | G17: готівковий | H17: ПІБ 906 | I17: Магазин №7 Київ | J17: 207.58 | K17: 43273 | L17: =VLOOKUP(D17, 'Список товарів'!$B$2:$D$341, 2, FALSE) -> Reebok
A18: 100000007 | B18: 43273 | C18: 0.65077546 | D18: 10335 | E18: 1 | F18: 1388.8756 | G18: готівковий | H18: ПІБ 906 | I18: Магазин №7 Київ | J18: 672.28 | K18: 43273 | L18: =VLOOKUP(D18, 'Список товарів'!$B$2:$D$341, 2, FALSE) -> Reebok
A19: 100000007 | B19: 43273 | C19: 0.65077546 | D19: 10031 | E19: 1 | F19: 105.21984 | G19: готівковий | H19: ПІБ 906 | I19: Магазин №7 Київ | J19: 53.76 | K19: 43273 | L19: =VLOOKUP(D19, 'Список товарів'!$B$2:$D$341, 2, FALSE) -> Nike
... A33: 100000014 | B33: 42452 | C33: 0.37737269 | D33: 10283 | E33: 1 | F33: 260.172 | G33: готівковий | H33: ПІБ 317 | I33: Магазин №4 Київ | J33: 131.4 | K33: 42452 | L33: =VLOOKUP(D33, 'Список товарів'!$B$2:$D$341, 2, FALSE) -> Reebok
A34: 100000015 | B34: 43219 | C34: 0.72944444 | D34: 10168 | E34: 1 | F34: 415.617 | G34: безготівковий | I34: Магазин №7 Київ | J34: 209.1 | K34: 43219 | L34: =VLOOKUP(D34, 'Список товарів'!$B$2:$D$341, 2, FALSE) -> Adidas
A35: 100000015 | B35: 43219 | C35: 0.72944444 | D35: 10304 | E35: 1 | F35: 788.424 | G35: безготівковий | I35: Магазин №7 Київ | J35: 368.6 | K35: 43219 | L35: =VLOOKUP(D35, 'Список товарів'!$B$2:$D$341, 2, FALSE) -> Reebok
A36: 100000015 | B36: 43219 | C36: 0.72944444 | D36: 10305 | E36: 1 | F36: 337.6813 | G36: безготівковий | I36: Магазин №7 Київ | J36: 178.18 | K36: 43219 | L36: =VLOOKUP(D36, 'Список товарів'!$B$2:$D$341, 2, FALSE) -> Reebok
A37: 100000015 | B37: 43219 | C37: 0.72944444 | D37: 10333 | E37: 2 | F37: 1676.2986 | G37: безготівковий | I37: Магазин №7 Київ | J37: 1057.32 | K37: 43219 | L37: =VLOOKUP(D37, 'Список товарів'!$B$2:$D$341, 2, FALSE) -> Reebok
A38: 100000017 | B38: 42838 | C38: 0.85396991 | D38: 10263 | E38: 1 | F38: 391.45824 | G38: готівковий | I38: Магазин №3 Київ | J38: 250.7 | K38: 42838 | L38: =VLOOKUP(D38, 'Список товарів'!$B$2:$D$341, 2, FALSE) -> Reebok
A39: 100000017 | B39: 42838 | C39: 0.85396991 | D39: 10082 | E39: 1 | F39: 1919.9152 | G39: готівковий | I39: Магазин №3 Київ | J39: 791.8 | K39: 42838 | L39: =VLOOKUP(D39, 'Список товарів'!$B$2:$D$341, 2, FALSE) -> Nike
A40: 100000017 | B40: 42838 | C40: 0.85396991 | D40: 10334 | E40: 1 | F40: 790.548 | G40: готівковий | I40: Магазин №3 Київ | J40: 339.9 | K40: 42838 | L40: =VLOOKUP(D40, 'Список товарів'!$B$2:$D$341, 2, FALSE) -> Reebok
A41: 100000017 | B41: 42838 | C41: 0.85396991 | D41: 10300 | E41: 1 | F41: 386.694 | G41: готівковий | I41: Магазин №3 Київ | J41: 228.9 | K41: 42838 | L41: =VLOOKUP(D41, 'Список товарів'!$B$2:$D$341, 2, FALSE) -> Reebok
A42: 100000019 | B42: 42486 | C42: 0.48730324 | D42: 10016 | E42: 1 | F42: 2573.2825 | G42: готівковий | I42: Магазин №6 Київ | J42: 1498.23 | K42: 42490 | L42: =VLOOKUP(D42, 'Список товарів'!$B$2:$D$341, 2, FALSE) -> Nike
A43: 100000021 | B43: 42663 | C43: 0.70542824 | D43: 10054 | E43: 1 | F43: 329.8696 | G43: готівковий | H43: ПІБ 146 | I43: Магазин №3 Київ | J43: 178 | K43: 42663 | L43: =VLOOKUP(D43, 'Список товарів'!$B$2:$D$341, 2, FALSE) -> Nike
A44: 100000022 | B44: 42519 | C44: 0.56890046 | D44: 10028 | E44: 2 | F44: 1785.3382 | G44: безготівковий | H44: ПІБ 358 | I44: Магазин №2 Київ | J44: 956.48 | K44: 42519 | L44: =VLOOKUP(D44, 'Список товарів'!$B$2:$D$341, 2, FALSE) -> Nike
A45: 100000025 | B45: 42461 | C45: 0.69945602 | D45: 10100 | E45: 1 | F45: 5889.38 | G45: готівковий | I45: Магазин №9 Дніпро | J45: 2849.7 | K45: 42461 | L45: =VLOOKUP(D45, 'Список товарів'!$B$2:$D$341, 2, FALSE) -> Adidas
A46: 100000025 | B46: 42461 | C46: 0.69945602 | D46: 10203 | E46: 1 | F46: 470.016 | G46: готівковий | I46: Магазин №9 Дніпро | J46: 336.96 | K46: 42461 | L46: =VLOOKUP(D46, 'Список товарів'!$B$2:$D$341, 2, FALSE) -> Puma
A47: 100000025 | B47: 42461 | C47: 0.69945602 | D47: 10008 | E47: 2 | F47: 1309.408 | G47: готівковий | I47: Магазин №9 Дніпро | J47: 690.56 | K47: 42461 | L47: =VLOOKUP(D47, 'Список товарів'!$B$2:$D$341, 2, FALSE) -> Nike
A48: 100000027 | B48: 43023 | C48: 0.76537037 | D48: 10304 | E48: 1 | F48: 629.356 | G48: готівковий | I48: Магазин №6 Київ | J48: 372.4 | K48: 43025 | L48: =VLOOKUP(D48, 'Список товарів'!$B$2:$D$341, 2, FALSE) -> Reebok
A49: 100000027 | B49: 43023 | C49: 0.76537037 | D49: 10167 | E49: 2 | F49: 4109.7196 | G49: готівковий | I49: Магазин №6 Київ | J49: 1910.64 | K49: 43025 | L49: =VLOOKUP(D49, 'Список товарів'!$B$2:$D$341, 2, FALSE) -> Adidas
A50: 100000027 | B50: 43023 | C50: 0.76537037 | D50: 10055 | E50: 1 | F50: 501.942 | G50: готівковий | I50: Магазин №6 Київ | J50: 190 | K50: 43025 | L50: =VLOOKUP(D50, 'Список товарів'!$B$2:$D$341, 2, FALSE) -> Nike
A51: 100000028 | B51: 42438 | C51: 0.58804398 | D51: 10169 | E51: 2 | F51: 939.62736 | G51: готівковий | I51: Магазин №8 Дніпро | J51: 632.4 | K51: 42439 | L51: =VLOOKUP(D51, 'Список товарів'!$B$2:$D$341, 2, FALSE) -> Adidas
A52: 100000029 | B52: 42599 | C52: 0.37606481 | D52: 10071 | E52: 1 | F52: 1031.1682 | G52: готівковий | I52: Магазин №6 Київ | J52: 605.85 | K52: 42601 | L52: =VLOOKUP(D52, 'Список товарів'!$B$2:$D$341, 2, FALSE) -> Nike
A53: 100000029 | B53: 42599 | C53: 0.37606481 | D53: 10183 | E53: 1 | F53: 5867.696 | G53: готівковий | I53: Магазин №6 Київ | J53: 4211.96 | K53: 42601 | L53: =VLOOKUP(D53, 'Список товарів'!$B$2:$D$341, 2, FALSE) -> Puma
...

Sheet Продажі магазин 10
A1: № чеку | B1: Дата продажу | C1: Рік | D1: Місяць | E1: День | F1: Товар ID | G1: Товар ID новий | H1: Кількість | I1: Ціна одиниці | J1: Виручка, грн | K1: Покупець | L1: Собівартість, грн | M1: Дата відвантаження | N1: Бренд
A2: 100000010 | B2: 42604 | C2: 2016 | D2: 8 | E2: 22 | F2: ХА-3417 | G2: =VLOOKUP(F2, 'Список товарів'!$A$2:$H$341, 2, FALSE) -> 10310 | H2: 1 | I2: 260.1312 | J2: 260.1312 | K2: ПІБ 537 | L2: 186.44 | M2: 42604 | N2: =VLOOKUP(G2, 'Список товарів'!$B$2:$D$341, 2, FALSE) -> Reebok
A3: 100000010 | B3: 42604 | C3: 2016 | D3: 8 | E3: 22 | F3: ХА-3381 | G3: =VLOOKUP(F3, 'Список товарів'!$A$2:$H$341, 2, FALSE) -> 10274 | H3: 1 | I3: 6228.9326 | J3: 6228.9326 | K3: ПІБ 537 | L3: 3166.08 | M3: 42604 | N3: =VLOOKUP(G3, 'Список товарів'!$B$2:$D$341, 2, FALSE) -> Reebok
A4: 100000012 | B4: 43167 | C4: 2018 | D4: 3 | E4: 8 | F4: ХА-3229 | G4: =VLOOKUP(F4, 'Список товарів'!$A$2:$H$341, 2, FALSE) -> 10122 | H4: 1 | I4: 248.34843 | J4: 248.34843 | L4: 167.89 | M4: 43170 | N4: =VLOOKUP(G4, 'Список товарів'!$B$2:$D$341, 2, FALSE) -> Adidas
A5: 100000012 | B5: 43167 | C5: 2018 | D5: 3 | E5: 8 | F5: ХА-3441 | G5: =VLOOKUP(F5, 'Список товарів'!$A$2:$H$341, 2, FALSE) -> 10334 | H5: 1 | I5: 657.624 | J5: 657.624 | L5: 320.1 | M5: 43170 | N5: =VLOOKUP(G5, 'Список товарів'!$B$2:$D$341, 2, FALSE) -> Reebok
A6: 100000013 | B6: 42684 | C6: 2016 | D6: 11 | E6: 10 | F6: ХА-3144 | G6: =VLOOKUP(F6, 'Список товарів'!$A$2:$H$341, 2, FALSE) -> 10037 | H6: 1 | I6: 499.7696 | J6: 499.7696 | L6: 274.8 | M6: 42684 | N6: =VLOOKUP(G6, 'Список товарів'!$B$2:$D$341, 2, FALSE) -> Nike
A7: 100000018 | B7: 42867 | C7: 2017 | D7: 5 | E7: 12 | F7: ХА-3413 | G7: =VLOOKUP(F7, 'Список товарів'!$A$2:$H$341, 2, FALSE) -> 10306 | H7: 2 | I7: 191.092 | J7: 382.184 | L7: 207.68 | M7: 42869 | N7: =VLOOKUP(G7, 'Список товарів'!$B$2:$D$341, 2, FALSE) -> Reebok
A8: 100000018 | B8: 42867 | C8: 2017 | D8: 5 | E8: 12 | F8: ХА-3404 | G8: =VLOOKUP(F8, 'Список товарів'!$A$2:$H$341, 2, FALSE) -> 10297 | H8: 1 | I8: 161.007 | J8: 161.007 | L8: 118.65 | M8: 42869 | N8: =VLOOKUP(G8, 'Список товарів'!$B$2:$D$341, 2, FALSE) -> Reebok
A9: 100000024 | B9: 42803 | C9: 2017 | D9: 3 | E9: 9 | F9: ХА-3305 | G9: =VLOOKUP(F9, 'Список товарів'!$A$2:$H$341, 2, FALSE) -> 10198 | H9: 1 | I9: 243.3536 | J9: 243.3536 | L9: 154 | M9: 42803 | N9: =VLOOKUP(G9, 'Список товарів'!$B$2:$D$341, 2, FALSE) -> Puma
A10: 100000030 | B10: 42572 | C10: 2016 | D10: 7 | E10: 21 | F10: ХА-3335 | G10: =VLOOKUP(F10, 'Список товарів'!$A$2:$H$341, 2, FALSE) -> 10228 | H10: 1 | I10: 279.50336 | J10: 279.50336 | L10: 169.28 | M10: 42577 | N10: =VLOOKUP(G10, 'Список товарів'!$B$2:$D$341, 2, FALSE) -> Puma
A11: 100000077 | B11: 43279 | C11: 2018 | D11: 6 | E11: 28 | F11: ХА-3238 | G11: =VLOOKUP(F11, 'Список товарів'!$A$2:$H$341, 2, FALSE) -> 10131 | H11: 2 | I11: 429.5112 | J11: 859.0224 | L11: 491.96 | M11: 43281 | N11: =VLOOKUP(G11, 'Список товарів'!$B$2:$D$341, 2, FALSE) -> Adidas
A12: 100000081 | B12: 42829 | C12: 2017 | D12: 4 | E12: 4 | F12: ХА-3152 | G12: =VLOOKUP(F12, 'Список товарів'!$A$2:$H$341, 2, FALSE) -> 10045 | H12: 2 | I12: 236.72 | J12: 473.44 | L12: 252.5 | M12: 42830 | N12: =VLOOKUP(G12, 'Список товарів'!$B$2:$D$341, 2, FALSE) -> Nike
A13: 100000081 | B13: 42829 | C13: 2017 | D13: 4 | E13: 4 | F13: ХА-3165 | G13: =VLOOKUP(F13, 'Список товарів'!$A$2:$H$341, 2, FALSE) -> 10058 | H13: 1 | I13: 641.88288 | J13: 641.88288 | L13: 223.86 | M13: 42830 | N13: =VLOOKUP(G13, 'Список товарів'!$B$2:$D$341, 2, FALSE) -> Nike
A14: 100000081 | B14: 42829 | C14: 2017 | D14: 4 | E14: 4 | F14: ХА-3174 | G14: =VLOOKUP(F14, 'Список товарів'!$A$2:$H$341, 2, FALSE) -> 10067 | H14: 1 | I14: 2505.0031 | J14: 2505.0031 | L14: 1189.44 | M14: 42830 | N14: =VLOOKUP(G14, 'Список товарів'!$B$2:$D$341, 2, FALSE) -> Nike
A15: 100000081 | B15: 42829 | C15: 2017 | D15: 4 | E15: 4 | F15: ХА-3435 | G15: =VLOOKUP(F15, 'Список товарів'!$A$2:$H$341, 2, FALSE) -> 10328 | H15: 2 | I15: 515.679 | J15: 1031.358 | L15: 473.1 | M15: 42830 | N15: =VLOOKUP(G15, 'Список товарів'!$B$2:$D$341, 2, FALSE) -> Reebok
... A22: 100000085 | B22: 42687 | C22: 2016 | D22: 11 | E22: 13 | F22: ХА-3202 | G22: =VLOOKUP(F22, 'Список товарів'!$A$2:$H$341, 2, FALSE) -> 10095 | H22: 1 | I22: 6199.7215 | J22: 6199.7215 | L22: 3269.63 | M22: 42687 | N22: =VLOOKUP(G22, 'Список товарів'!$B$2:$D$341, 2, FALSE) -> Adidas
A23: 100000086 | B23: 42660 | C23: 2016 | D23: 10 | E23: 17 | F23: ХА-3182 | G23: =VLOOKUP(F23, 'Список товарів'!$A$2:$H$341, 2, FALSE) -> 10075 | H23: 1 | I23: 1600.0102 | J23: 1600.0102 | K23: ПІБ 504 | L23: 741.6 | M23: 42665 | N23: =VLOOKUP(G23, 'Список товарів'!$B$2:$D$341, 2, FALSE) -> Nike
A24: 100000105 | B24: 43147 | C24: 2018 | D24: 2 | E24: 16 | F24: ХА-3340 | G24: =VLOOKUP(F24, 'Список товарів'!$A$2:$H$341, 2, FALSE) -> 10233 | H24: 1 | I24: 991.38125 | J24: 991.38125 | L24: 572.3 | M24: 43147 | N24: =VLOOKUP(G24, 'Список товарів'!$B$2:$D$341, 2, FALSE) -> Puma
A25: 100000105 | B25: 43147 | C25: 2018 | D25: 2 | E25: 16 | F25: ХА-3342 | G25: =VLOOKUP(F25, 'Список товарів'!$A$2:$H$341, 2, FALSE) -> 10235 | H25: 1 | I25: 1331.3737 | J25: 1331.3737 | L25: 946.57 | M25: 43147 | N25: =VLOOKUP(G25, 'Список товарів'!$B$2:$D$341, 2, FALSE) -> Puma
A26: 100000105 | B26: 43147 | C26: 2018 | D26: 2 | E26: 16 | F26: ХА-3425 | G26: =VLOOKUP(F26, 'Список товарів'!$A$2:$H$341, 2, FALSE) -> 10318 | H26: 1 | I26: 379.1037 | J26: 379.1037 | L26: 160.59 | M26: 43147 | N26: =VLOOKUP(G26, 'Список товарів'!$B$2:$D$341, 2, FALSE) -> Reebok
A27: 100000105 | B27: 43147 | C27: 2018 | D27: 2 | E27: 16 | F27: ХА-3183 | G27: =VLOOKUP(F27, 'Список товарів'!$A$2:$H$341, 2, FALSE) -> 10076 | H27: 1 | I27: 1524.2509 | J27: 1524.2509 | L27: 804.58 | M27: 43147 | N27: =VLOOKUP(G27, 'Список товарів'!$B$2:$D$341, 2, FALSE) -> Nike
A28: 100000105 | B28: 43147 | C28: 2018 | D28: 2 | E28: 16 | F28: ХА-3200 | G28: =VLOOKUP(F28, 'Список товарів'!$A$2:$H$341, 2, FALSE) -> 10093 | H28: 1 | I28: 603.30774 | J28: 603.30774 | L28: 339.08 | M28: 43147 | N28: =VLOOKUP(G28, 'Список товарів'!$B$2:$D$341, 2, FALSE) -> Adidas
A29: 100000105 | B29: 43147 | C29: 2018 | D29: 2 | E29: 16 | F29: ХА-3321 | G29: =VLOOKUP(F29, 'Список товарів'!$A$2:$H$341, 2, FALSE) -> 10214 | H29: 2 | I29: 226.2708 | J29: 452.5416 | L29: 275.52 | M29: 43147 | N29: =VLOOKUP(G29, 'Список товарів'!$B$2:$D$341, 2, FALSE) -> Puma
A30: 100000105 | B30: 43147 | C30: 2018 | D30: 2 | E30: 16 | F30: ХА-3170 | G30: =VLOOKUP(F30, 'Список товарів'!$A$2:$H$341, 2, FALSE) -> 10063 | H30: 1 | I30: 1279.9441 | J30: 1279.9441 | L30: 555.21 | M30: 43147 | N30: =VLOOKUP(G30, 'Список товарів'!$B$2:$D$341, 2, FALSE) -> Nike
A31: 100000110 | B31: 43162 | C31: 2018 | D31: 3 | E31: 3 | F31: ХА-3195 | G31: =VLOOKUP(F31, 'Список товарів'!$A$2:$H$341, 2, FALSE) -> 10088 | H31: 1 | I31: 3241.26 | J31: 3241.26 | L31: 1473.3 | M31: 43162 | N31: =VLOOKUP(G31, 'Список товарів'!$B$2:$D$341, 2, FALSE) -> Adidas
A32: 100000110 | B32: 43162 | C32: 2018 | D32: 3 | E32: 3 | F32: ХА-3270 | G32: =VLOOKUP(F32, 'Список товарів'!$A$2:$H$341, 2, FALSE) -> 10163 | H32: 1 | I32: 1318.6912 | J32: 1318.6912 | L32: 763.42 | M32: 43162 | N32: =VLOOKUP(G32, 'Список товарів'!$B$2:$D$341, 2, FALSE) -> Adidas
A33: 100000110 | B33: 43162 | C33: 2018 | D33: 3 | E33: 3 | F33: ХА-3237 | G33: =VLOOKUP(F33, 'Список товарів'!$A$2:$H$341, 2, FALSE) -> 10130 | H33: 1 | I33: 109.6704 | J33: 109.6704 | L33: 60.48 | M33: 43162 | N33: =VLOOKUP(G33, 'Список товарів'!$B$2:$D$341, 2, FALSE) -> Adidas
A34: 100000110 | B34: 43162 | C34: 2018 | D34: 3 | E34: 3 | F34: ХА-3153 | G34: =VLOOKUP(F34, 'Список товарів'!$A$2:$H$341, 2, FALSE) -> 10046 | H34: 1 | I34: 410.06936 | J34: 410.06936 | L34: 200.55 | M34: 43162 | N34: =VLOOKUP(G34, 'Список товарів'!$B$2:$D$341, 2, FALSE) -> Nike
A35: 100000110 | B35: 43162 | C35: 2018 | D35: 3 | E35: 3 | F35: ХА-3176 | G35: =VLOOKUP(F35, 'Список товарів'!$A$2:$H$341, 2, FALSE) -> 10069 | H35: 1 | I35: 1266.2503 | J35: 1266.2503 | L35: 728.14 | M35: 43162 | N35: =VLOOKUP(G35, 'Список товарів'!$B$2:$D$341, 2, FALSE) -> Nike
... A39: 100000119 | B39: 42731 | C39: 2016 | D39: 12 | E39: 27 | F39: ХА-3386 | G39: =VLOOKUP(F39, 'Список товарів'!$A$2:$H$341, 2, FALSE) -> 10279 | H39: 1 | I39: 660.4542 | J39: 660.4542 | L39: 333.9 | M39: 42731 | N39: =VLOOKUP(G39, 'Список товарів'!$B$2:$D$341, 2, FALSE) -> Reebok
A40: 100000134 | B40: 43000 | C40: 2017 | D40: 9 | E40: 22 | F40: ХА-3256 | G40: =VLOOKUP(F40, 'Список товарів'!$A$2:$H$341, 2, FALSE) -> 10149 | H40: 1 | I40: 1845.299 | J40: 1845.299 | K40: ПІБ 1051 | L40: 1002.82 | M40: 43005 | N40: =VLOOKUP(G40, 'Список товарів'!$B$2:$D$341, 2, FALSE) -> Adidas
A41: 100000146 | B41: 43095 | C41: 2017 | D41: 12 | E41: 26 | F41: ХА-3224 | G41: =VLOOKUP(F41, 'Список товарів'!$A$2:$H$341, 2, FALSE) -> 10117 | H41: 1 | I41: 86.94 | J41: 86.94 | L41: 47.25 | M41: 43095 | N41: =VLOOKUP(G41, 'Список товарів'!$B$2:$D$341, 2, FALSE) -> Adidas
A42: 100000146 | B42: 43095 | C42: 2017 | D42: 12 | E42: 26 | F42: ХА-3280 | G42: =VLOOKUP(F42, 'Список товарів'!$A$2:$H$341, 2, FALSE) -> 10173 | H42: 1 | I42: 2124.2798 | J42: 2124.2798 | L42: 1906.05 | M42: 43095 | N42: =VLOOKUP(G42, 'Список товарів'!$B$2:$D$341, 2, FALSE) -> Puma
A43: 100000146 | B43: 43095 | C43: 2017 | D43: 12 | E43: 26 | F43: ХА-3232 | G43: =VLOOKUP(F43, 'Список товарів'!$A$2:$H$341, 2, FALSE) -> 10125 | H43: 1 | I43: 230.0672 | J43: 230.0672 | L43: 147.44 | M43: 43095 | N43: =VLOOKUP(G43, 'Список товарів'!$B$2:$D$341, 2, FALSE) -> Adidas
A44: 100000146 | B44: 43095 | C44: 2017 | D44: 12 | E44: 26 | F44: ХА-3186 | G44: =VLOOKUP(F44, 'Список товарів'!$A$2:$H$341, 2, FALSE) -> 10079 | H44: 1 | I44: 1739.1629 | J44: 1739.1629 | L44: 779.22 | M44: 43095 | N44: =VLOOKUP(G44, 'Список товарів'!$B$2:$D$341, 2, FALSE) -> Nike
A45: 100000146 | B45: 43095 | C45: 2017 | D45: 12 | E45: 26 | F45: ХА-3322 | G45: =VLOOKUP(F45, 'Список товарів'!$A$2:$H$341, 2, FALSE) -> 10215 | H45: 1 | I45: 432.77978 | J45: 432.77978 | L45: 282.7 | M45: 43095 | N45: =VLOOKUP(G45, 'Список товарів'!$B$2:$D$341, 2, FALSE) -> Puma
A46: 100000149 | B46: 43322 | C46: 2018 | D46: 8 | E46: 10 | F46: ХА-3394 | G46: =VLOOKUP(F46, 'Список товарів'!$A$2:$H$341, 2, FALSE) -> 10287 | H46: 1 | I46: 114.1254 | J46: 114.1254 | L46: 47.94 | M46: 43326 | N46: =VLOOKUP(G46, 'Список товарів'!$B$2:$D$341, 2, FALSE) -> Reebok
A47: 100000149 | B47: 43322 | C47: 2018 | D47: 8 | E47: 10 | F47: ХА-3233 | G47: =VLOOKUP(F47, 'Список товарів'!$A$2:$H$341, 2, FALSE) -> 10126 | H47: 1 | I47: 299.439 | J47: 299.439 | L47: 204.75 | M47: 43326 | N47: =VLOOKUP(G47, 'Список товарів'!$B$2:$D$341, 2, FALSE) -> Adidas
A48: 100000155 | B48: 43059 | C48: 2017 | D48: 11 | E48: 20 | F48: ХА-3211 | G48: =VLOOKUP(F48, 'Список товарів'!$A$2:$H$341, 2, FALSE) -> 10104 | H48: 1 | I48: 3296.1576 | J48: 3296.1576 | L48: 2037.6 | M48: 43063 | N48: =VLOOKUP(G48, 'Список товарів'!$B$2:$D$341, 2, FALSE) -> Adidas
A49: 100000194 | B49: 42710 | C49: 2016 | D49: 12 | E49: 6 | F49: ХА-3387 | G49: =VLOOKUP(F49, 'Список товарів'!$A$2:$H$341, 2, FALSE) -> 10280 | H49: 1 | I49: 479.52 | J49: 479.52 | L49: 234 | M49: 42710 | N49: =VLOOKUP(G49, 'Список товарів'!$B$2:$D$341, 2, FALSE) -> Reebok
...

Sheet Список магазинів
A1: ID магазину | B1: Назва магазину | C1: Місто | D1: Координати, широта | E1: Координати, довгота | F1: Площа, кв.м. | G1: Кількість продавців
A2: 1 | B2: Київ Центральний №1 | C2: Київ | D2: 50.440561 | E2: 30.522595 | F2: 101 | G2: 2
A3: 2 | B3: Київ Поділ №2 | C3: Київ | D3: 50.460275 | E3: 30.628835 | F3: 210 | G3: 5
A4: 3 | B4: Київ Осокорки №3 | C4: Київ | D4: 50.4041 | E4: 30.561468 | F4: 240 | G4: 6
A5: 4 | B5: Київ Позняки №4 | C5: Київ | D5: 50.433236 | E5: 30.532072 | F5: 226 | G5: 6
A6: 5 | B6: Київ ЦУМ №5 | C6: Київ | D6: 50.50522 | E6: 30.458173 | F6: 125 | G6: 3
A7: 6 | B7: Київ №6 | C7: Київ | D7: 50.411125 | E7: 30.383865 | F7: 187 | G7: 4
A8: 7 | B8: Київ №7 | C8: Київ | D8: 50.398375 | E8: 30.635775 | F8: 165 | G8: 4
A9: 8 | B9: Дніпро Короленко №8 | C9: Дніпро | D9: 48.462446 | E9: 35.049245 | F9: 115 | G9: 2
A10: 9 | B10: Дніпро Музей №9 | C10: Дніпро | D10: 48.464992 | E10: 35.028807 | F10: 192 | G10: 4
A11: 10 | B11: Харків №10 Проспект | C11: Харків | D11: 49.988384 | E11: 36.232701 | F11: 201 | G11: 3

Sheet Список товарів
A1: ID старий (по Харкову) | B1: ID новий | C1: Бренд | D1: Найменування товару | E1: Категорія товару | F1: Розмір | G1: Колір | H1: Стать
A2: ХА-3108 | B2: 10001 | C2: Nike | D2: Кросівки тип 1 | E2: Взуття | F2: 40 | G2: бежевий | H2: Чол.
A3: ХА-3109 | B3: 10002 | C3: Nike | D3: Кросівки тип 2 | E3: Взуття | F3: 39 | G3: чорний | H3: Чол.
A4: ХА-3110 | B4: 10003 | C4: Nike | D4: Кросівки тип 3 | E4: Взуття | F4: 40 | G4: білий | H4: Жін.
A5: ХА-3111 | B5: 10004 | C5: Nike | D5: Кросівки тип 4 | E5: Взуття | F5: 44 | G5: жовтий | H5: Чол.
A6: ХА-3112 | B6: 10005 | C6: Nike | D6: Кросівки тип 5 | E6: Взуття | F6: 42 | G6: чорний | H6: Чол.
A7: ХА-3113 | B7: 10006 | C7: Nike | D7: Кросівки тип 6 | E7: Взуття | F7: 40 | G7: білий | H7: Жін.
A8: ХА-3114 | B8: 10007 | C8: Nike | D8: Босоніжки тип 1 | E8: Взуття | F8: 43 | G8: білий | H8: Жін.
A9: ХА-3115 | B9: 10008 | C9: Nike | D9: Босоніжки тип 2 | E9: Взуття | F9: 40 | G9: бежевий | H9: Жін.
A10: ХА-3116 | B10: 10009 | C10: Nike | D10: Босоніжки тип 3 | E10: Взуття | F10: 37 | G10: білий | H10: Жін.
A11: ХА-3117 | B11: 10010 | C11: Nike | D11: Чоботи тип 1 | E11: Взуття | F11: 45 | G11: чорний | H11: Жін.
A12: ХА-3118 | B12: 10011 | C12: Nike | D12: Чоботи тип 2 | E12: Взуття | F12: 44 | G12: зелений | H12: Чол.
A13: ХА-3119 | B13: 10012 | C13: Nike | D13: Чоботи тип 3 | E13: Взуття | F13: 45 | G13: чорний | H13: Жін.
... A20: ХА-3126 | B20: 10019 | C20: Nike | D20: Туфлі тип 4 | E20: Взуття | F20: 39 | G20: чорний | H20: Жін.
A21: ХА-3127 | B21: 10020 | C21: Nike | D21: Ремінь тип 1 | E21: Аксесуари | F21: б/р | G21: бірюзовий | H21: Унісекс
A22: ХА-3128 | B22: 10021 | C22: Nike | D22: Ремінь тип 2 | E22: Аксесуари | F22: б/р | G22: чорний | H22: Унісекс
A23: ХА-3129 | B23: 10022 | C23: Nike | D23: Ремінь тип 3 | E23: Аксесуари | F23: б/р | G23: жовтий | H23: Унісекс
A24: ХА-3130 | B24: 10023 | C24: Nike | D24: Ремінь тип 4 | E24: Аксесуари | F24: б/р | G24: білий | H24: Унісекс
A25: ХА-3131 | B25: 10024 | C25: Nike | D25: Запонка тип 1 | E25: Аксесуари | F25: б/р | G25: зелений | H25: Унісекс
A26: ХА-3132 | B26: 10025 | C26: Nike | D26: Запонка тип 2 | E26: Аксесуари | F26: б/р | G26: зелений | H26: Унісекс
A27: ХА-3133 | B27: 10026 | C27: Nike | D27: Запонка тип 3 | E27: Аксесуари | F27: б/р | G27: чорний | H27: Унісекс
A28: ХА-3134 | B28: 10027 | C28: Nike | D28: Запонка тип 4 | E28: Аксесуари | F28: б/р | G28: червоний | H28: Унісекс
A29: ХА-3135 | B29: 10028 | C29: Nike | D29: Запонка тип 5 | E29: Аксесуари | F29: б/р | G29: чорний | H29: Унісекс
A30: ХА-3136 | B30: 10029 | C30: Nike | D30: Запонка тип 6 | E30: Аксесуари | F30: б/р | G30: червоний | H30: Унісекс
A31: ХА-3137 | B31: 10030 | C31: Nike | D31: Запонка тип 7 | E31: Аксесуари | F31: б/р | G31: чорний | H31: Унісекс
A32: ХА-3138 | B32: 10031 | C32: Nike | D32: М'ячик тип 1 | E32: Аксесуари | F32: б/р | G32: білий | H32: Унісекс
... A86: ХА-3192 | B86: 10085 | C86: Nike | D86: Сорочка тип 12 | E86: Верхній одяг | F86: S | G86: чорний | H86: Жін.
A87: ХА-3193 | B87: 10086 | C87: Adidas | D87: Кросівки тип 1 | E87: Взуття | F87: 39 | G87: чорний | H87: Жін.
A88: ХА-3194 | B88: 10087 | C88: Adidas | D88: Кросівки тип 2 | E88: Взуття | F88: 45 | G88: червоний | H88: Жін.
A89: ХА-3195 | B89: 10088 | C89: Adidas | D89: Кросівки тип 3 | E89: Взуття | F89: 40 | G89: чорний | H89: Чол.
A90: ХА-3196 | B90: 10089 | C90: Adidas | D90: Кросівки тип 4 | E90: Взуття | F90: 41 | G90: зелений | H90: Жін.
A91: ХА-3197 | B91: 10090 | C91: Adidas | D91: Кросівки тип 5 | E91: Взуття | F91: 41 | G91: чорний | H91: Жін.
A92: ХА-3198 | B92: 10091 | C92: Adidas | D92: Кросівки тип 6 | E92: Взуття | F92: 38 | G92: чорний | H92: Чол.
A93: ХА-3199 | B93: 10092 | C93: Adidas | D93: Босоніжки тип 1 | E93: Взуття | F93: 41 | G93: бежевий | H93: Чол.
A94: ХА-3200 | B94: 10093 | C94: Adidas | D94: Босоніжки тип 2 | E94: Взуття | F94: 39 | G94: чорний | H94: Жін.
A95: ХА-3201 | B95: 10094 | C95: Adidas | D95: Босоніжки тип 3 | E95: Взуття | F95: 43 | G95: червоний | H95: Жін.
A96: ХА-3202 | B96: 10095 | C96: Adidas | D96: Чоботи тип 1 | E96: Взуття | F96: 44 | G96: білий | H96: Жін.
A97: ХА-3203 | B97: 10096 | C97: Adidas | D97: Чоботи тип 2 | E97: Взуття | F97: 37 | G97: бірюзовий | H97: Жін.
A98: ХА-3204 | B98: 10097 | C98: Adidas | D98: Чоботи тип 3 | E98: Взуття | F98: 38 | G98: білий | H98: Чол.
... A105: ХА-3211 | B105: 10104 | C105: Adidas | D105: Туфлі тип 4 | E105: Взуття | F105: 41 | G105: червоний | H105: Жін.
...

Sheet Клієнти
A1: Покупець | B1: Стать | C1: Зайнятість | D1: Рік народження | E1: Телефон | F1: Канал залучення
A2: ПІБ 1 | B2: Ч | C2: Держслужбовець | D2: 1962 | E2: 064-652-8882 | F2: Друзі
A3: ПІБ 2 | B3: Ч | C3: Самозайнятий | D3: 1975 | E3: 074-463-5451 | F3: Друзі
A4: ПІБ 3 | B4: Ж | C4: Офісний співробітник | D4: 1975 | E4: 094-719-8155 | F4: Друзі
A5: ПІБ 4 | B5: Ж | C5: Держслужбовець | D5: 1967 | E5: 043-495-8736 | F5: Інтернет
A6: ПІБ 5 | B6: Ч | C6: Студент | D6: 1985 | E6: 027-676-4836 | F6: Інтернет
A7: ПІБ 6 | B7: Ж | C7: Офісний співробітник | D7: 1975 | E7: 047-392-7932 | F7: Зовнішня реклама
A8: ПІБ 7 | B8: Ч | C8: Самозайнятий | D8: 1984 | E8: 061-682-3541 | F8: Друзі
A9: ПІБ 8 | B9: Ж | C9: Самозайнятий | D9: 1978 | E9: 084-587-1275 | F9: Друзі
A10: ПІБ 9 | B10: Ч | C10: Офісний співробітник | D10: 1986 | E10: 093-248-1394 | F10: Зовнішня реклама
A11: ПІБ 10 | B11: Ч | C11: Держслужбовець | D11: 1972 | E11: 024-569-8134 | F11: Радіо
A12: ПІБ 11 | B12: Ч | C12: Офісний співробітник | D12: 1971 | E12: 049-583-8154 | F12: Друзі
A13: ПІБ 12 | B13: Ч | C13: Держслужбовець | D13: 1985 | E13: 043-871-2763 | F13: Друзі
... A1279: ПІБ 1278 | B1279: Ж | C1279: Держслужбовець | D1279: 1968 | E1279: 055-872-2622 | F1279: Інтернет

Sheet Відвідувачі
A1: Дата | B1: Магазин | C1: Зайшло клієнтів
A2: 42370 | B2: 1 | C2: 27
A3: 42370 | B3: 2 | C3: 10
A4: 42370 | B4: 3 | C4: 15
A5: 42370 | B5: 4 | C5: 18
A6: 42370 | B6: 5 | C6: 5
A7: 42370 | B7: 6 | C7: 3
A8: 42370 | B8: 7 | C8: 9
A9: 42370 | B9: 8 | C9: 20
A10: 42370 | B10: 9 | C10: 15
A11: 42370 | B11: 10 | C11: 14
A12: 42371 | B12: 1 | C12: 6
A13: 42371 | B13: 2 | C13: 30
... A10031: 43373 | B10031: 10 | C10031: 13
